<?xml version="1.0"?>
<robot name="cretus" xmlns:xacro="http://ros.org/wiki/xacro">

    <!-- Dummy base-->
    <link name="dummy_base"/>

    <!-- Base link-->
    <link name="base_link">
      <visual>
          <geometry>
              <mesh filename="package://cretus/meshes/main_body.dae" />
              <!-- <cylinder length="0.10938" radius="0.178"/> -->
          </geometry>
          <origin xyz="0.001 0 0.05199" rpy="0 0 0"/>
      </visual>
      <collision>
          <geometry>
              <cylinder length="0.10938" radius="0.178"/>
          </geometry>
          <origin xyz="0.0 0 0.05949" rpy="0 0 0"/>
      </collision>
      <inertial>
          <origin xyz="0.01 0 0"/>
          <mass value="2.4"/>
          <inertia ixx="0.019995" ixy="0.0" ixz="0.0"
          iyy="0.019995" iyz="0.0"
          izz="0.03675"/>
      </inertial>
    </link>

    <gazebo reference="base_link">
      <mu1>0.3</mu1>
      <mu2>0.3</mu2>
    </gazebo>

    <!-- Base joint-->
    <joint name="base_joint" type="fixed">
      <origin xyz="0 0 0.0102" rpy="0 0 0" />
      <parent link="dummy_base"/>
      <child link="base_link" />
    </joint>

    <!-- Left wheel-->
    <link name="wheel_left_link">
      <visual>
        <geometry>
          <mesh filename="package://cretus/meshes/wheel.dae"/>
          <!-- <cylinder length="0.0206" radius="0.035"/> -->
        </geometry>
        <origin xyz="0 0 0" rpy="0 0 0"/>
      </visual>
      <collision>
        <geometry>
          <cylinder length="0.0206" radius="0.035"/>
        </geometry>
        <origin rpy="0 0 0" xyz="0 0 0"/>
      </collision>
      <inertial>
        <mass value="0.01" />
        <origin xyz="0 0 0" />
        <inertia ixx="0.001" ixy="0.0" ixz="0.0"
                  iyy="0.001" iyz="0.0"
                  izz="0.001" />
      </inertial>
    </link>

    <gazebo reference="wheel_left_link">
      <mu1>1.0</mu1>
      <mu2>1.0</mu2>
      <kp>1000000.0</kp>
      <kd>100.0</kd>
      <minDepth>0.001</minDepth>
      <maxVel>1.0</maxVel>
    </gazebo>

    <!-- Left base joint-->
    <joint name="wheel_left_joint" type="continuous">
      <parent link="base_link"/>
      <child link="wheel_left_link"/>
      <origin xyz="0.00 ${0.23/2} 0.0250" rpy="-1.571 0 0"/>
      <axis xyz="0 0 1"/>
    </joint>

     <!-- Left wheel transmission-->
    <transmission name="left_wheel_trans" type="SimpleTransmission">
        <type>transmission_interface/SimpleTransmission</type>
        <actuator name="left_wheel_motor">
            <mechanicalReduction>1</mechanicalReduction>
            <hardwareInterface>hardware_interface/VelocityJointInterface</hardwareInterface>
        </actuator>
        <joint name="wheel_left_joint">
            <hardwareInterface>hardware_interface/VelocityJointInterface</hardwareInterface>
        </joint>
    </transmission>
      
    <!-- Right wheel link-->
    <link name="wheel_right_link">
      <visual>
        <geometry>
          <mesh filename="package://cretus/meshes/wheel.dae"/>
          <!-- <cylinder length="0.0206" radius="0.035"/> -->
        </geometry>
        <origin xyz="0 0 0" rpy="0 0 0"/>
      </visual>
      <collision>
        <geometry>
          <cylinder length="0.0206" radius="0.035"/>
        </geometry>
        <origin rpy="0 0 0" xyz="0 0 0"/>
      </collision>
      <inertial>
        <mass value="0.01" />
        <origin xyz="0 0 0" />
        <inertia ixx="0.001" ixy="0.0" ixz="0.0"
                  iyy="0.001" iyz="0.0"
                  izz="0.001" />
      </inertial>
    </link>

    <gazebo reference="wheel_right_link">
      <mu1>1.0</mu1>
      <mu2>1.0</mu2>
      <kp>1000000.0</kp>
      <kd>100.0</kd>
      <minDepth>0.001</minDepth>
      <maxVel>1.0</maxVel>
    </gazebo>

    <!-- Right wheel joint-->
    <joint name="wheel_right_joint" type="continuous">
      <parent link="base_link"/>
      <child link="wheel_right_link"/>
      <origin xyz="0.00 -${0.23/2} 0.0250" rpy="-1.571 0 0"/>
      <axis xyz="0 0 1"/>
    </joint>

    <!-- Right wheel transmission-->
    <transmission name="right_wheel_trans" type="SimpleTransmission">
        <type>transmission_interface/SimpleTransmission</type>
        <actuator name="right_wheel_motor">
            <mechanicalReduction>1</mechanicalReduction>
            <hardwareInterface>hardware_interface/VelocityJointInterface</hardwareInterface>
        </actuator>
        <joint name="wheel_right_joint">
            <hardwareInterface>hardware_interface/VelocityJointInterface</hardwareInterface>
        </joint>
    </transmission>

    <!-- Front caster wheel-->
    <link name="caster_front_link">
      <visual>
          <geometry>
              <cylinder length="0.0176" radius="0.017"/>
          </geometry>
      </visual>
      <collision>
        <geometry>
          <cylinder length="0.0176" radius="0.017"/>
        </geometry>
        <origin rpy="0 0 0" xyz="0 0 0"/>
      </collision>
      <inertial>
        <mass value="0.01" />
        <origin xyz="0 0 0" />
        <inertia ixx="0.001" ixy="0.0" ixz="0.0"
                  iyy="0.001" iyz="0.0"
                  izz="0.001" />
      </inertial>
    </link>

    <gazebo reference="caster_front_link">
      <mu1>0.0</mu1>
      <mu2>0.0</mu2>
      <kp>1000000.0</kp>
      <kd>100.0</kd>
      <minDepth>0.001</minDepth>
      <maxVel>1.0</maxVel>
    </gazebo>

    <!-- Front caster joint-->
    <joint name="caster_front_joint" type="fixed">
      <parent link="base_link"/>
      <child link="caster_front_link"/>
      <origin xyz="0.115 0.0 0.007" rpy="-1.571 0 0"/>
    </joint>

    <!-- Back caster joint-->
    <link name="caster_back_link">
      <visual>
        <geometry>
            <cylinder length="0.0176" radius="0.017"/>
        </geometry>
      </visual>
      <collision>
        <geometry>
          <cylinder length="0.0176" radius="0.017"/>
        </geometry>
        <origin rpy="0 0 0" xyz="0 0 0"/>
      </collision>
      <inertial>
        <mass value="0.01" />
        <origin xyz="0 0 0" />
        <inertia ixx="0.001" ixy="0.0" ixz="0.0"
                 iyy="0.001" iyz="0.0"
                 izz="0.001" />
      </inertial>
    </link>

    <gazebo reference="caster_back_link">
      <mu1>0.0</mu1>
      <mu2>0.0</mu2>
      <kp>1000000.0</kp>
      <kd>100.0</kd>
      <minDepth>0.001</minDepth>
      <maxVel>1.0</maxVel>
    </gazebo>

    <!-- Back caster joint-->
    <joint name="caster_back_joint" type="fixed">
      <parent link="base_link"/>
      <child link="caster_back_link"/>
      <origin xyz="-0.135 0.0 0.009" rpy="-1.571 0 0"/>
    </joint>

    <!-- Gazebo control plugins-->
    <gazebo>
        <plugin name="gazebo_ros_control" filename= "libgazebo_ros_control.so">
         <robotNamespace>/</robotNamespace>
        </plugin>
    </gazebo>

</robot>